2025-01-24 15:52:24,784:ERROR:{'message': ZeroDivisionError('division by zero'), 'detail': 'Traceback (most recent call last):\n  File "C:\\Users\\Home\\python_exception\\context_manager.py", line 19, in write_on_log_error\n    yield\n  File "C:\\Users\\Home\\python_exception\\context_manager.py", line 30, in <module>\n    10 / 0\n    ~~~^~~\nZeroDivisionError: division by zero\n'}
2025-01-24 15:53:29,217:ERROR:{'message': 'division by zero', 'detail': 'Traceback (most recent call last):\n  File "C:\\Users\\Home\\python_exception\\context_manager.py", line 19, in write_on_log_error\n    yield\n  File "C:\\Users\\Home\\python_exception\\context_manager.py", line 30, in <module>\n    10 / 0\n    ~~~^~~\nZeroDivisionError: division by zero\n'}
